<?xml version="1.0"?>

<robot name="quadrotor" xmlns:xacro="http://www.ros.org/wiki/xacro">
    <!--quadrotor_base-->
    <xacro:include filename="$(find hector_quadrotor_description)/urdf/quadrotor_base.urdf.xacro" />
    <xacro:quadrotor_base_macro />

    <!--link to camera-->
    <joint name="base_fixed_joint" type="fixed">
      <origin xyz="0.28 0 0" rpy="0 0 0"/>
      <parent link="base_link"/>
      <child link="base_fixed_link"/>
    </joint>
    <link name="base_fixed_link">
      <inertial>
        <mass value="0.001" />
        <origin xyz="0 0 0" rpy="0 0 0" />
        <inertia ixx="1.0e-6" ixy="0.0" ixz="0.0" iyy="1.0e-6" iyz="0.0" izz="1.0e-6" />
      </inertial>
      <visual>
        <origin xyz="0.075 -0.005 0" rpy="0 0 0" />
        <geometry>
          <box size="0.15 0.01 0.02" />
        </geometry>
      </visual>
      <collision>
        <origin xyz="0.075 -0.005 0" rpy="0 0 0" />
        <geometry>
          <box size="0.15 0.01 0.02" />
        </geometry>
      </collision>
    </link>
    <joint name="camera_joint" type="revolute">
      <origin xyz="0.14 0 0" rpy="0 0 0"/>
      <limit upper="1.5708" lower="-1.5708" velocity="10.0" effort="0.001"/>
      <axis xyz="0 1 0" />
      <parent link="base_fixed_link"/>
      <child link="camera_link"/>
    </joint>
    <link name="camera_link">
      <inertial>
        <mass value="0.001" />
        <origin xyz="0 0 0" rpy="0 0 0" />
        <inertia ixx="1.0e-6" ixy="0.0" ixz="0.0" iyy="1.0e-6" iyz="0.0" izz="1.0e-6" />
      </inertial>
      <visual>
        <origin xyz="0 0.005 0" rpy="0 0 0" />
        <geometry>
          <box size="0.03 0.01 0.02" />
        </geometry>
      </visual>
      <collision>
        <origin xyz="0 0.005 0" rpy="0 0 0" />
        <geometry>
          <box size="0.03 0.01 0.02" />
        </geometry>
      </collision>
    </link>

    <!-- add two links and joints for controlling the depth camera rs435 -->
    <xacro:include filename="$(find aircraft_scanning_description)/urdf/rgbd_camera.urdf.xacro"/>
    <xacro:camera_macro parent="camera_link">
      <origin xyz="0.035 0 0" rpy="0 0 0"/>
    </xacro:camera_macro>

    <gazebo reference="base_fixed_link">
      <material>Gazebo/Orange</material>
    </gazebo>
    <gazebo reference="camera_link">
      <material>Gazebo/Yellow</material>
    </gazebo>
    <!--transmission for joint-->
    <transmission name="camera_tran">
      <type>transmission_interface/SimpleTransmission</type>
      <joint name="camera_joint">
        <hardwareInterface>EffortJointInterface</hardwareInterface>
      </joint>
      <actuator name="camera_motor">
        <hardwareInterface>EffortJointInterface</hardwareInterface>
        <mechanicalReduction>1</mechanicalReduction>
      </actuator>
    </transmission>
    <gazebo>
      <plugin name="gazebo_ros_control" filename="libgazebo_ros_control.so">
        <robotNamespace>/uav_scanning</robotNamespace>
        <robotSimType>gazebo_ros_control/DefaultRobotHWSim</robotSimType>
        <legacyModeNS>true</legacyModeNS>
      </plugin>
    </gazebo>

    <xacro:include filename="$(find hector_quadrotor_gazebo)/urdf/quadrotor_plugins.gazebo.xacro" />

</robot>
